{
  "nbformat": 4,
  "nbformat_minor": 0,
  "metadata": {
    "colab": {
      "provenance": [],
      "authorship_tag": "ABX9TyMMWjqAcAV9p7GaTTlCz4Sf",
      "include_colab_link": true
    },
    "kernelspec": {
      "name": "python3",
      "display_name": "Python 3"
    },
    "language_info": {
      "name": "python"
    }
  },
  "cells": [
    {
      "cell_type": "markdown",
      "metadata": {
        "id": "view-in-github",
        "colab_type": "text"
      },
      "source": [
        "<a href=\"https://colab.research.google.com/github/tamoghna21/RAG_LLM/blob/main/1_RL_Stock_FinRL.ipynb\" target=\"_parent\"><img src=\"https://colab.research.google.com/assets/colab-badge.svg\" alt=\"Open In Colab\"/></a>"
      ]
    },
    {
      "cell_type": "code",
      "execution_count": null,
      "metadata": {
        "id": "xNeWZ8J8HAS2"
      },
      "outputs": [],
      "source": []
    },
    {
      "cell_type": "code",
      "source": [
        "\n",
        "## install required packages\n",
        "!pip install numpy==1.23.5\n",
        "!pip install swig\n",
        "!pip install wrds\n",
        "!pip install pyportfolioopt\n",
        "## install finrl library\n",
        "!pip install git+https://github.com/AI4Finance-Foundation/FinRL.git\n"
      ],
      "metadata": {
        "colab": {
          "base_uri": "https://localhost:8080/",
          "height": 1000
        },
        "id": "lFCU-joVHBPc",
        "outputId": "bd3db866-4134-48ef-f857-816c588be5d6"
      },
      "execution_count": null,
      "outputs": [
        {
          "output_type": "stream",
          "name": "stdout",
          "text": [
            "Collecting numpy==1.23.5\n",
            "  Downloading numpy-1.23.5-cp310-cp310-manylinux_2_17_x86_64.manylinux2014_x86_64.whl (17.1 MB)\n",
            "\u001b[2K     \u001b[90m━━━━━━━━━━━━━━━━━━━━━━━━━━━━━━━━━━━━━━━━\u001b[0m \u001b[32m17.1/17.1 MB\u001b[0m \u001b[31m36.5 MB/s\u001b[0m eta \u001b[36m0:00:00\u001b[0m\n",
            "\u001b[?25hInstalling collected packages: numpy\n",
            "  Attempting uninstall: numpy\n",
            "    Found existing installation: numpy 1.25.2\n",
            "    Uninstalling numpy-1.25.2:\n",
            "      Successfully uninstalled numpy-1.25.2\n",
            "\u001b[31mERROR: pip's dependency resolver does not currently take into account all the packages that are installed. This behaviour is the source of the following dependency conflicts.\n",
            "chex 0.1.86 requires numpy>=1.24.1, but you have numpy 1.23.5 which is incompatible.\n",
            "pandas-stubs 2.0.3.230814 requires numpy>=1.25.0; python_version >= \"3.9\", but you have numpy 1.23.5 which is incompatible.\u001b[0m\u001b[31m\n",
            "\u001b[0mSuccessfully installed numpy-1.23.5\n"
          ]
        },
        {
          "output_type": "display_data",
          "data": {
            "application/vnd.colab-display-data+json": {
              "pip_warning": {
                "packages": [
                  "numpy"
                ]
              },
              "id": "f8012915c84746649c2f952cccbe0b5f"
            }
          },
          "metadata": {}
        },
        {
          "output_type": "stream",
          "name": "stdout",
          "text": [
            "Collecting swig\n",
            "  Downloading swig-4.2.1-py2.py3-none-manylinux_2_5_x86_64.manylinux1_x86_64.whl (1.9 MB)\n",
            "\u001b[?25l     \u001b[90m━━━━━━━━━━━━━━━━━━━━━━━━━━━━━━━━━━━━━━━━\u001b[0m \u001b[32m0.0/1.9 MB\u001b[0m \u001b[31m?\u001b[0m eta \u001b[36m-:--:--\u001b[0m\r\u001b[2K     \u001b[91m━━━━━━━━━━━━━━━━━━━━━\u001b[0m\u001b[91m╸\u001b[0m\u001b[90m━━━━━━━━━━━━━━━━━━\u001b[0m \u001b[32m1.0/1.9 MB\u001b[0m \u001b[31m30.3 MB/s\u001b[0m eta \u001b[36m0:00:01\u001b[0m\r\u001b[2K     \u001b[90m━━━━━━━━━━━━━━━━━━━━━━━━━━━━━━━━━━━━━━━━\u001b[0m \u001b[32m1.9/1.9 MB\u001b[0m \u001b[31m29.2 MB/s\u001b[0m eta \u001b[36m0:00:00\u001b[0m\n",
            "\u001b[?25hTraceback (most recent call last):\n",
            "  File \"/usr/local/lib/python3.10/dist-packages/pip/_vendor/pkg_resources/__init__.py\", line 3108, in _dep_map\n",
            "    return self.__dep_map\n",
            "  File \"/usr/local/lib/python3.10/dist-packages/pip/_vendor/pkg_resources/__init__.py\", line 2901, in __getattr__\n",
            "    raise AttributeError(attr)\n",
            "AttributeError: _DistInfoDistribution__dep_map\n",
            "\n",
            "During handling of the above exception, another exception occurred:\n",
            "\n",
            "Traceback (most recent call last):\n",
            "  File \"/usr/local/lib/python3.10/dist-packages/pip/_internal/cli/base_command.py\", line 169, in exc_logging_wrapper\n",
            "    status = run_func(*args)\n",
            "  File \"/usr/local/lib/python3.10/dist-packages/pip/_internal/cli/req_command.py\", line 242, in wrapper\n",
            "    return func(self, options, args)\n",
            "  File \"/usr/local/lib/python3.10/dist-packages/pip/_internal/commands/install.py\", line 441, in run\n",
            "    conflicts = self._determine_conflicts(to_install)\n",
            "  File \"/usr/local/lib/python3.10/dist-packages/pip/_internal/commands/install.py\", line 572, in _determine_conflicts\n",
            "    return check_install_conflicts(to_install)\n",
            "  File \"/usr/local/lib/python3.10/dist-packages/pip/_internal/operations/check.py\", line 101, in check_install_conflicts\n",
            "    package_set, _ = create_package_set_from_installed()\n",
            "  File \"/usr/local/lib/python3.10/dist-packages/pip/_internal/operations/check.py\", line 42, in create_package_set_from_installed\n",
            "    dependencies = list(dist.iter_dependencies())\n",
            "  File \"/usr/local/lib/python3.10/dist-packages/pip/_internal/metadata/pkg_resources.py\", line 216, in iter_dependencies\n",
            "    return self._dist.requires(extras)\n",
            "  File \"/usr/local/lib/python3.10/dist-packages/pip/_vendor/pkg_resources/__init__.py\", line 2821, in requires\n",
            "    dm = self._dep_map\n",
            "  File \"/usr/local/lib/python3.10/dist-packages/pip/_vendor/pkg_resources/__init__.py\", line 3110, in _dep_map\n",
            "    self.__dep_map = self._compute_dependencies()\n",
            "  File \"/usr/local/lib/python3.10/dist-packages/pip/_vendor/pkg_resources/__init__.py\", line 3120, in _compute_dependencies\n",
            "    reqs.extend(parse_requirements(req))\n",
            "  File \"/usr/local/lib/python3.10/dist-packages/pip/_vendor/pkg_resources/__init__.py\", line 3173, in __init__\n",
            "    super(Requirement, self).__init__(requirement_string)\n",
            "  File \"/usr/local/lib/python3.10/dist-packages/pip/_vendor/packaging/requirements.py\", line 102, in __init__\n",
            "    req = REQUIREMENT.parseString(requirement_string)\n",
            "  File \"/usr/local/lib/python3.10/dist-packages/pip/_vendor/pyparsing/core.py\", line 1131, in parse_string\n",
            "    loc, tokens = self._parse(instring, 0)\n",
            "  File \"/usr/local/lib/python3.10/dist-packages/pip/_vendor/pyparsing/core.py\", line 817, in _parseNoCache\n",
            "    loc, tokens = self.parseImpl(instring, pre_loc, doActions)\n",
            "  File \"/usr/local/lib/python3.10/dist-packages/pip/_vendor/pyparsing/core.py\", line 3886, in parseImpl\n",
            "    loc, exprtokens = e._parse(instring, loc, doActions)\n",
            "  File \"/usr/local/lib/python3.10/dist-packages/pip/_vendor/pyparsing/core.py\", line 817, in _parseNoCache\n",
            "    loc, tokens = self.parseImpl(instring, pre_loc, doActions)\n",
            "  File \"/usr/local/lib/python3.10/dist-packages/pip/_vendor/pyparsing/core.py\", line 4114, in parseImpl\n",
            "    return e._parse(\n",
            "  File \"/usr/local/lib/python3.10/dist-packages/pip/_vendor/pyparsing/core.py\", line 817, in _parseNoCache\n",
            "    loc, tokens = self.parseImpl(instring, pre_loc, doActions)\n",
            "  File \"/usr/local/lib/python3.10/dist-packages/pip/_vendor/pyparsing/core.py\", line 3864, in parseImpl\n",
            "    loc, resultlist = self.exprs[0]._parse(\n",
            "  File \"/usr/local/lib/python3.10/dist-packages/pip/_vendor/pyparsing/core.py\", line 776, in _parseNoCache\n",
            "    def _parseNoCache(\n",
            "KeyboardInterrupt\n",
            "\n",
            "During handling of the above exception, another exception occurred:\n",
            "\n",
            "Traceback (most recent call last):\n",
            "  File \"/usr/lib/python3.10/logging/__init__.py\", line 1732, in isEnabledFor\n",
            "    return self._cache[level]\n",
            "KeyError: 50\n",
            "\n",
            "During handling of the above exception, another exception occurred:\n",
            "\n",
            "Traceback (most recent call last):\n",
            "  File \"/usr/local/bin/pip3\", line 8, in <module>\n",
            "    sys.exit(main())\n",
            "  File \"/usr/local/lib/python3.10/dist-packages/pip/_internal/cli/main.py\", line 79, in main\n",
            "    return command.main(cmd_args)\n",
            "  File \"/usr/local/lib/python3.10/dist-packages/pip/_internal/cli/base_command.py\", line 101, in main\n",
            "    return self._main(args)\n",
            "  File \"/usr/local/lib/python3.10/dist-packages/pip/_internal/cli/base_command.py\", line 223, in _main\n",
            "    return run(options, args)\n",
            "  File \"/usr/local/lib/python3.10/dist-packages/pip/_internal/cli/base_command.py\", line 206, in exc_logging_wrapper\n",
            "    logger.critical(\"Operation cancelled by user\")\n",
            "  File \"/usr/lib/python3.10/logging/__init__.py\", line 1523, in critical\n",
            "    if self.isEnabledFor(CRITICAL):\n",
            "  File \"/usr/lib/python3.10/logging/__init__.py\", line 1732, in isEnabledFor\n",
            "    return self._cache[level]\n",
            "KeyboardInterrupt\n",
            "^C\n",
            "Collecting wrds\n",
            "  Downloading wrds-3.2.0-py3-none-any.whl (13 kB)\n"
          ]
        }
      ]
    },
    {
      "cell_type": "code",
      "source": [
        "!pip install numpy==1.23.5"
      ],
      "metadata": {
        "colab": {
          "base_uri": "https://localhost:8080/",
          "height": 412
        },
        "id": "lfx-EODlQZXO",
        "outputId": "1ada19f4-8e77-45f8-a804-c4eff4d0df33"
      },
      "execution_count": null,
      "outputs": [
        {
          "output_type": "stream",
          "name": "stderr",
          "text": [
            "/usr/local/lib/python3.10/dist-packages/ipykernel/ipkernel.py:283: DeprecationWarning: `should_run_async` will not call `transform_cell` automatically in the future. Please pass the result to `transformed_cell` argument and any exception that happen during thetransform in `preprocessing_exc_tuple` in IPython 7.17 and above.\n",
            "  and should_run_async(code)\n"
          ]
        },
        {
          "output_type": "stream",
          "name": "stdout",
          "text": [
            "Collecting numpy==1.23.5\n",
            "  Downloading numpy-1.23.5-cp310-cp310-manylinux_2_17_x86_64.manylinux2014_x86_64.whl (17.1 MB)\n",
            "\u001b[2K     \u001b[90m━━━━━━━━━━━━━━━━━━━━━━━━━━━━━━━━━━━━━━━━\u001b[0m \u001b[32m17.1/17.1 MB\u001b[0m \u001b[31m46.2 MB/s\u001b[0m eta \u001b[36m0:00:00\u001b[0m\n",
            "\u001b[?25hInstalling collected packages: numpy\n",
            "  Attempting uninstall: numpy\n",
            "    Found existing installation: numpy 1.26.4\n",
            "    Uninstalling numpy-1.26.4:\n",
            "      Successfully uninstalled numpy-1.26.4\n",
            "\u001b[31mERROR: pip's dependency resolver does not currently take into account all the packages that are installed. This behaviour is the source of the following dependency conflicts.\n",
            "chex 0.1.86 requires numpy>=1.24.1, but you have numpy 1.23.5 which is incompatible.\n",
            "cudf-cu12 24.4.1 requires pandas<2.2.2dev0,>=2.0, but you have pandas 2.2.2 which is incompatible.\n",
            "pandas-stubs 2.0.3.230814 requires numpy>=1.25.0; python_version >= \"3.9\", but you have numpy 1.23.5 which is incompatible.\n",
            "wrds 3.2.0 requires numpy<1.27,>=1.26, but you have numpy 1.23.5 which is incompatible.\u001b[0m\u001b[31m\n",
            "\u001b[0mSuccessfully installed numpy-1.23.5\n"
          ]
        },
        {
          "output_type": "display_data",
          "data": {
            "application/vnd.colab-display-data+json": {
              "pip_warning": {
                "packages": [
                  "numpy"
                ]
              },
              "id": "9ae686fdcebb424d8907466810bc25fb"
            }
          },
          "metadata": {}
        }
      ]
    },
    {
      "cell_type": "code",
      "source": [
        "import pandas as pd\n",
        "import numpy as np\n",
        "import datetime\n",
        "import yfinance as yf\n",
        "\n",
        "from finrl.meta.preprocessor.yahoodownloader import YahooDownloader\n",
        "from finrl.meta.preprocessor.preprocessors import FeatureEngineer, data_split\n",
        "from finrl import config_tickers\n",
        "from finrl.config import INDICATORS\n",
        "\n",
        "import itertools"
      ],
      "metadata": {
        "id": "zzpP3XGTLyxU"
      },
      "execution_count": null,
      "outputs": []
    }
  ]
}